2024-08-02 02:57:21,669 INFO: generate [in /Users/bilal/Documents/comsc/kings/individual-project/Tokenize/backend/app/ai/routes.py:57]
2024-08-02 02:57:21,781 INFO: check_code [in /Users/bilal/Documents/comsc/kings/individual-project/Tokenize/backend/app/ai/routes.py:57]
2024-08-02 02:57:27,520 INFO: document [in /Users/bilal/Documents/comsc/kings/individual-project/Tokenize/backend/app/ai/routes.py:57]
2024-08-02 03:01:23,087 INFO: Flask API startup [in /Users/bilal/Documents/comsc/kings/individual-project/Tokenize/backend/app/__init__.py:71]
2024-08-02 03:01:29,602 INFO: Flask API startup [in /Users/bilal/Documents/comsc/kings/individual-project/Tokenize/backend/app/__init__.py:71]
2024-08-02 03:15:04,362 INFO: Flask API startup [in /Users/bilal/Documents/comsc/kings/individual-project/Tokenize/backend/app/__init__.py:71]
2024-08-02 03:22:46,717 INFO: Flask API startup [in /Users/bilal/Documents/comsc/kings/individual-project/Tokenize/backend/app/__init__.py:71]
2024-08-02 03:27:42,277 INFO: Flask API startup [in /Users/bilal/Documents/comsc/kings/individual-project/Tokenize/backend/app/__init__.py:71]
2024-08-02 03:44:56,800 INFO: Flask API startup [in /Users/bilal/Documents/comsc/kings/individual-project/Tokenize/backend/app/__init__.py:71]
2024-08-02 03:48:11,252 INFO: Flask API startup [in /Users/bilal/Documents/comsc/kings/individual-project/Tokenize/backend/app/__init__.py:71]
2024-08-02 03:52:10,026 ERROR: Exception on /api/users/user [PUT] [in /Users/bilal/Documents/PassportGPT/.venv/backend/lib/python3.11/site-packages/flask/app.py:1414]
Traceback (most recent call last):
  File "/Users/bilal/Documents/PassportGPT/.venv/backend/lib/python3.11/site-packages/sqlalchemy/engine/base.py", line 1963, in _exec_single_context
    self.dialect.do_execute(
  File "/Users/bilal/Documents/PassportGPT/.venv/backend/lib/python3.11/site-packages/sqlalchemy/engine/default.py", line 918, in do_execute
    cursor.execute(statement, parameters)
psycopg2.errors.StringDataRightTruncation: value too long for type character varying(120)


The above exception was the direct cause of the following exception:

Traceback (most recent call last):
  File "/Users/bilal/Documents/PassportGPT/.venv/backend/lib/python3.11/site-packages/flask/app.py", line 2190, in wsgi_app
    response = self.full_dispatch_request()
               ^^^^^^^^^^^^^^^^^^^^^^^^^^^^
  File "/Users/bilal/Documents/PassportGPT/.venv/backend/lib/python3.11/site-packages/flask/app.py", line 1486, in full_dispatch_request
    rv = self.handle_user_exception(e)
         ^^^^^^^^^^^^^^^^^^^^^^^^^^^^^
  File "/Users/bilal/Documents/PassportGPT/.venv/backend/lib/python3.11/site-packages/flask_cors/extension.py", line 165, in wrapped_function
    return cors_after_request(app.make_response(f(*args, **kwargs)))
                                                ^^^^^^^^^^^^^^^^^^
  File "/Users/bilal/Documents/PassportGPT/.venv/backend/lib/python3.11/site-packages/flask/app.py", line 1484, in full_dispatch_request
    rv = self.dispatch_request()
         ^^^^^^^^^^^^^^^^^^^^^^^
  File "/Users/bilal/Documents/PassportGPT/.venv/backend/lib/python3.11/site-packages/flask/app.py", line 1469, in dispatch_request
    return self.ensure_sync(self.view_functions[rule.endpoint])(**view_args)
           ^^^^^^^^^^^^^^^^^^^^^^^^^^^^^^^^^^^^^^^^^^^^^^^^^^^^^^^^^^^^^^^^^
  File "/Users/bilal/Documents/PassportGPT/.venv/backend/lib/python3.11/site-packages/flask_jwt_extended/view_decorators.py", line 154, in decorator
    return current_app.ensure_sync(fn)(*args, **kwargs)
           ^^^^^^^^^^^^^^^^^^^^^^^^^^^^^^^^^^^^^^^^^^^^
  File "/Users/bilal/Documents/comsc/kings/individual-project/Tokenize/backend/app/users/routes.py", line 104, in update_user_profile
    db.session.commit()
  File "/Users/bilal/Documents/PassportGPT/.venv/backend/lib/python3.11/site-packages/sqlalchemy/orm/scoping.py", line 553, in commit
    return self._proxied.commit()
           ^^^^^^^^^^^^^^^^^^^^^^
  File "/Users/bilal/Documents/PassportGPT/.venv/backend/lib/python3.11/site-packages/sqlalchemy/orm/session.py", line 1905, in commit
    trans.commit(_to_root=True)
  File "<string>", line 2, in commit
  File "/Users/bilal/Documents/PassportGPT/.venv/backend/lib/python3.11/site-packages/sqlalchemy/orm/state_changes.py", line 137, in _go
    ret_value = fn(self, *arg, **kw)
                ^^^^^^^^^^^^^^^^^^^^
  File "/Users/bilal/Documents/PassportGPT/.venv/backend/lib/python3.11/site-packages/sqlalchemy/orm/session.py", line 1220, in commit
    self._prepare_impl()
  File "<string>", line 2, in _prepare_impl
  File "/Users/bilal/Documents/PassportGPT/.venv/backend/lib/python3.11/site-packages/sqlalchemy/orm/state_changes.py", line 137, in _go
    ret_value = fn(self, *arg, **kw)
                ^^^^^^^^^^^^^^^^^^^^
  File "/Users/bilal/Documents/PassportGPT/.venv/backend/lib/python3.11/site-packages/sqlalchemy/orm/session.py", line 1195, in _prepare_impl
    self.session.flush()
  File "/Users/bilal/Documents/PassportGPT/.venv/backend/lib/python3.11/site-packages/sqlalchemy/orm/session.py", line 4153, in flush
    self._flush(objects)
  File "/Users/bilal/Documents/PassportGPT/.venv/backend/lib/python3.11/site-packages/sqlalchemy/orm/session.py", line 4289, in _flush
    with util.safe_reraise():
  File "/Users/bilal/Documents/PassportGPT/.venv/backend/lib/python3.11/site-packages/sqlalchemy/util/langhelpers.py", line 147, in __exit__
    raise exc_value.with_traceback(exc_tb)
  File "/Users/bilal/Documents/PassportGPT/.venv/backend/lib/python3.11/site-packages/sqlalchemy/orm/session.py", line 4250, in _flush
    flush_context.execute()
  File "/Users/bilal/Documents/PassportGPT/.venv/backend/lib/python3.11/site-packages/sqlalchemy/orm/unitofwork.py", line 467, in execute
    rec.execute(self)
  File "/Users/bilal/Documents/PassportGPT/.venv/backend/lib/python3.11/site-packages/sqlalchemy/orm/unitofwork.py", line 644, in execute
    util.preloaded.orm_persistence.save_obj(
  File "/Users/bilal/Documents/PassportGPT/.venv/backend/lib/python3.11/site-packages/sqlalchemy/orm/persistence.py", line 85, in save_obj
    _emit_update_statements(
  File "/Users/bilal/Documents/PassportGPT/.venv/backend/lib/python3.11/site-packages/sqlalchemy/orm/persistence.py", line 890, in _emit_update_statements
    c = connection.execute(
        ^^^^^^^^^^^^^^^^^^^
  File "/Users/bilal/Documents/PassportGPT/.venv/backend/lib/python3.11/site-packages/sqlalchemy/engine/base.py", line 1413, in execute
    return meth(
           ^^^^^
  File "/Users/bilal/Documents/PassportGPT/.venv/backend/lib/python3.11/site-packages/sqlalchemy/sql/elements.py", line 483, in _execute_on_connection
    return connection._execute_clauseelement(
           ^^^^^^^^^^^^^^^^^^^^^^^^^^^^^^^^^^
  File "/Users/bilal/Documents/PassportGPT/.venv/backend/lib/python3.11/site-packages/sqlalchemy/engine/base.py", line 1637, in _execute_clauseelement
    ret = self._execute_context(
          ^^^^^^^^^^^^^^^^^^^^^^
  File "/Users/bilal/Documents/PassportGPT/.venv/backend/lib/python3.11/site-packages/sqlalchemy/engine/base.py", line 1841, in _execute_context
    return self._exec_single_context(
           ^^^^^^^^^^^^^^^^^^^^^^^^^^
  File "/Users/bilal/Documents/PassportGPT/.venv/backend/lib/python3.11/site-packages/sqlalchemy/engine/base.py", line 1982, in _exec_single_context
    self._handle_dbapi_exception(
  File "/Users/bilal/Documents/PassportGPT/.venv/backend/lib/python3.11/site-packages/sqlalchemy/engine/base.py", line 2339, in _handle_dbapi_exception
    raise sqlalchemy_exception.with_traceback(exc_info[2]) from e
  File "/Users/bilal/Documents/PassportGPT/.venv/backend/lib/python3.11/site-packages/sqlalchemy/engine/base.py", line 1963, in _exec_single_context
    self.dialect.do_execute(
  File "/Users/bilal/Documents/PassportGPT/.venv/backend/lib/python3.11/site-packages/sqlalchemy/engine/default.py", line 918, in do_execute
    cursor.execute(statement, parameters)
sqlalchemy.exc.DataError: (psycopg2.errors.StringDataRightTruncation) value too long for type character varying(120)

[SQL: UPDATE users SET metamask_wallet_address=%(metamask_wallet_address)s WHERE users.id = %(users_id)s::UUID]
[parameters: {'metamask_wallet_address': 'gAAAAABmrEna8xw5aaTlX-rdBIgw8V2fZd786doTdxqnmfOWU1sowBk2BqSa8dQuDIQCqbTo1jfoblGJ71OC1iXF1c-GSho5dlgozLvjuAiG24BVDOYdGf3X6TyUNE36FAEpDMwxftDVy7rkiC7yhtUOmHgDrHfbQ8ot-KA7bDtvJLIjrUjUOB0=', 'users_id': UUID('1a110fb7-50f6-4301-bb84-538fbf1c705a')}]
(Background on this error at: https://sqlalche.me/e/20/9h9h)
2024-08-02 03:52:52,141 INFO: Flask API startup [in /Users/bilal/Documents/comsc/kings/individual-project/Tokenize/backend/app/__init__.py:71]
2024-08-02 03:52:58,587 INFO: Flask API startup [in /Users/bilal/Documents/comsc/kings/individual-project/Tokenize/backend/app/__init__.py:71]
2024-08-02 03:53:03,117 INFO: Flask API startup [in /Users/bilal/Documents/comsc/kings/individual-project/Tokenize/backend/app/__init__.py:71]
2024-08-02 04:00:50,668 INFO: Flask API startup [in /Users/bilal/Documents/comsc/kings/individual-project/Tokenize/backend/app/__init__.py:71]
